<?xml version="1.0" encoding="UTF-8"?>
<testsuite name="others"
           tests="4"
           failures="4"
           errors="0"
           skipped="0"
           time="590.315">
  <properties />
            <testcase name="hotStartLocationTime" time="68.974" classname="others.OthersTest">
                <failure type="java.lang.AssertionError"
                  message="超过60s还未定位 expected [成功] but found [失败]"
              >
<![CDATA[java.lang.AssertionError: 超过60s还未定位 expected [成功] but found [失败]
  org.testng.Assert.fail(Assert.java:94)
  org.testng.Assert.failNotEquals(Assert.java:496)
  org.testng.Assert.assertEquals(Assert.java:125)
  org.testng.Assert.assertEquals(Assert.java:178)
  others.OthersTest.hotStartLocationTime(OthersTest.java:131)
  sun.reflect.NativeMethodAccessorImpl.invoke0(Native Method)
  sun.reflect.NativeMethodAccessorImpl.invoke(Unknown Source)
  sun.reflect.DelegatingMethodAccessorImpl.invoke(Unknown Source)
  java.lang.reflect.Method.invoke(Unknown Source)
  org.testng.internal.MethodInvocationHelper.invokeMethod(MethodInvocationHelper.java:85)
  org.testng.internal.Invoker.invokeMethod(Invoker.java:639)
  org.testng.internal.Invoker.invokeTestMethod(Invoker.java:816)
  org.testng.internal.Invoker.invokeTestMethods(Invoker.java:1124)
  org.testng.internal.TestMethodWorker.invokeTestMethods(TestMethodWorker.java:125)
  org.testng.internal.TestMethodWorker.run(TestMethodWorker.java:108)
  java.util.concurrent.ThreadPoolExecutor.runWorker(Unknown Source)
  java.util.concurrent.ThreadPoolExecutor$Worker.run(Unknown Source)
  java.lang.Thread.run(Unknown Source)
]]>
      </failure>

          </testcase>
            <testcase name="airplaneToNormalMode" time="199.455" classname="others.OthersTest">
                <failure type="java.lang.AssertionError"
                  message="退出飞行模式后入网失败 expected [1] but found [0]"
              >
<![CDATA[java.lang.AssertionError: 退出飞行模式后入网失败 expected [1] but found [0]
  org.testng.Assert.fail(Assert.java:94)
  org.testng.Assert.failNotEquals(Assert.java:496)
  org.testng.Assert.assertEquals(Assert.java:125)
  org.testng.Assert.assertEquals(Assert.java:372)
  others.OthersTest.airplaneToNormalMode(OthersTest.java:194)
  sun.reflect.NativeMethodAccessorImpl.invoke0(Native Method)
  sun.reflect.NativeMethodAccessorImpl.invoke(Unknown Source)
  sun.reflect.DelegatingMethodAccessorImpl.invoke(Unknown Source)
  java.lang.reflect.Method.invoke(Unknown Source)
  org.testng.internal.MethodInvocationHelper.invokeMethod(MethodInvocationHelper.java:85)
  org.testng.internal.Invoker.invokeMethod(Invoker.java:639)
  org.testng.internal.Invoker.invokeTestMethod(Invoker.java:816)
  org.testng.internal.Invoker.invokeTestMethods(Invoker.java:1124)
  org.testng.internal.TestMethodWorker.invokeTestMethods(TestMethodWorker.java:125)
  org.testng.internal.TestMethodWorker.run(TestMethodWorker.java:108)
  java.util.concurrent.ThreadPoolExecutor.runWorker(Unknown Source)
  java.util.concurrent.ThreadPoolExecutor$Worker.run(Unknown Source)
  java.lang.Thread.run(Unknown Source)
]]>
      </failure>

          </testcase>
            <testcase name="sosToNormalMode" time="252.304" classname="others.OthersTest">
                <failure type="java.lang.AssertionError"
                  message="退出sos模式后入网失败 expected [1] but found [0]"
              >
<![CDATA[java.lang.AssertionError: 退出sos模式后入网失败 expected [1] but found [0]
  org.testng.Assert.fail(Assert.java:94)
  org.testng.Assert.failNotEquals(Assert.java:496)
  org.testng.Assert.assertEquals(Assert.java:125)
  org.testng.Assert.assertEquals(Assert.java:372)
  others.OthersTest.sosToNormalMode(OthersTest.java:165)
  sun.reflect.NativeMethodAccessorImpl.invoke0(Native Method)
  sun.reflect.NativeMethodAccessorImpl.invoke(Unknown Source)
  sun.reflect.DelegatingMethodAccessorImpl.invoke(Unknown Source)
  java.lang.reflect.Method.invoke(Unknown Source)
  org.testng.internal.MethodInvocationHelper.invokeMethod(MethodInvocationHelper.java:85)
  org.testng.internal.Invoker.invokeMethod(Invoker.java:639)
  org.testng.internal.Invoker.invokeTestMethod(Invoker.java:816)
  org.testng.internal.Invoker.invokeTestMethods(Invoker.java:1124)
  org.testng.internal.TestMethodWorker.invokeTestMethods(TestMethodWorker.java:125)
  org.testng.internal.TestMethodWorker.run(TestMethodWorker.java:108)
  java.util.concurrent.ThreadPoolExecutor.runWorker(Unknown Source)
  java.util.concurrent.ThreadPoolExecutor$Worker.run(Unknown Source)
  java.lang.Thread.run(Unknown Source)
]]>
      </failure>

          </testcase>
            <testcase name="fastDialer" time="69.582" classname="others.OthersTest">
                <failure type="java.lang.AssertionError"
                  message="超时未接通或中途被挂断 expected [0] but found [1]"
              >
<![CDATA[java.lang.AssertionError: 超时未接通或中途被挂断 expected [0] but found [1]
  org.testng.Assert.fail(Assert.java:94)
  org.testng.Assert.failNotEquals(Assert.java:496)
  org.testng.Assert.assertEquals(Assert.java:125)
  org.testng.Assert.assertEquals(Assert.java:372)
  others.OthersTest.fastDialer(OthersTest.java:79)
  sun.reflect.NativeMethodAccessorImpl.invoke0(Native Method)
  sun.reflect.NativeMethodAccessorImpl.invoke(Unknown Source)
  sun.reflect.DelegatingMethodAccessorImpl.invoke(Unknown Source)
  java.lang.reflect.Method.invoke(Unknown Source)
  org.testng.internal.MethodInvocationHelper.invokeMethod(MethodInvocationHelper.java:85)
  org.testng.internal.Invoker.invokeMethod(Invoker.java:639)
  org.testng.internal.Invoker.invokeTestMethod(Invoker.java:816)
  org.testng.internal.Invoker.invokeTestMethods(Invoker.java:1124)
  org.testng.internal.TestMethodWorker.invokeTestMethods(TestMethodWorker.java:125)
  org.testng.internal.TestMethodWorker.run(TestMethodWorker.java:108)
  java.util.concurrent.ThreadPoolExecutor.runWorker(Unknown Source)
  java.util.concurrent.ThreadPoolExecutor$Worker.run(Unknown Source)
  java.lang.Thread.run(Unknown Source)
]]>
      </failure>

          </testcase>
  
  
  
</testsuite>
