<?xml version="1.0" encoding="UTF-8"?>
<!-- Generated by org.testng.reporters.JUnitXMLReporter -->
<testsuite hostname="gh-PC" name="dialer" tests="3" failures="1" timestamp="1 Apr 2020 05:27:47 GMT" time="230.007" errors="0">
  <testcase name="addNumToContact" time="24.557" classname="dialer.DialerTest"/>
  <testcase name="handDialing" time="69.315" classname="dialer.DialerTest"/>
  <testcase name="contactDialing" time="79.58" classname="dialer.DialerTest">
    <failure type="java.lang.AssertionError" message="The following asserts failed:
	未接通或中途被挂断 expected [0] but found [1]">
      <![CDATA[java.lang.AssertionError: The following asserts failed:
	未接通或中途被挂断 expected [0] but found [1]
	at org.testng.asserts.SoftAssert.assertAll(SoftAssert.java:43)
	at dialer.DialerTest.contactDialing(DialerTest.java:135)
	at sun.reflect.NativeMethodAccessorImpl.invoke0(Native Method)
	at sun.reflect.NativeMethodAccessorImpl.invoke(Unknown Source)
	at sun.reflect.DelegatingMethodAccessorImpl.invoke(Unknown Source)
	at java.lang.reflect.Method.invoke(Unknown Source)
	at org.testng.internal.MethodInvocationHelper.invokeMethod(MethodInvocationHelper.java:85)
	at org.testng.internal.Invoker.invokeMethod(Invoker.java:639)
	at org.testng.internal.Invoker.invokeTestMethod(Invoker.java:816)
	at org.testng.internal.Invoker.invokeTestMethods(Invoker.java:1124)
	at org.testng.internal.TestMethodWorker.invokeTestMethods(TestMethodWorker.java:125)
	at org.testng.internal.TestMethodWorker.run(TestMethodWorker.java:108)
	at java.util.concurrent.ThreadPoolExecutor.runWorker(Unknown Source)
	at java.util.concurrent.ThreadPoolExecutor$Worker.run(Unknown Source)
	at java.lang.Thread.run(Unknown Source)
]]>
    </failure>
  </testcase> <!-- contactDialing -->
</testsuite> <!-- dialer -->
